Workbook

Sheet اردیبهشت
A1: کد پرسنلی | B1: نام و نام خانوادگی کارمند | C1: ماه | D1: بیمه درمان تکمیلی | E1: جمع اقساط وام | F1: صندوق کارکنان مامور
A2: 1905 | B2: مجتبی جعفری | C2: 2
A3: 3567 | B3: محمدمهدی نصرهرندی | C3: 2
A4: 3607 | B4: امیررضا مومن | C4: 2 | D4: 32400000
A5: 3653 | B5: محمدعلی پیوست | C5: 2 | D5: 32400000
A6: 4590 | B6: معصومه توانای خشگرودی | C6: 2
A7: 4597 | B7: مجید محمدی | C7: 2 | D7: 25920000
A8: 4598 | B8: سیدمهدی میری | C8: 2 | D8: 25920000 | E8: 40000000
A9: 4614 | B9: محمد مهدی اطهر | C9: 2 | D9: 19440000
A10: 4621 | B10: سیدعباس مرادی | C10: 2 | E10: 13285793
A11: 4622 | B11: محمدرضا احمدلو | C11: 2 | D11: 25920000
A12: 4636 | B12: سید مصطفی معصوم پور | C12: 2 | D12: 32400000
A13: 4640 | B13: سیده فاطمه شجاعیان | C13: 2 | D13: 19440000
A14: 4643 | B14: سعید مهدیون | C14: 2
A15: 4648 | B15: حسن شبانی | C15: 2 | D15: 19440000
A16: 4651 | B16: حسین حقیقت پور | C16: 2 | D16: 19440000
A17: 4653 | B17: امیر شیخ حسنی | C17: 2 | D17: 32400000 | E17: 25000000
A18: 4654 | B18: مهران احمدی آذر | C18: 2 | D18: 19440000 | E18: 24000000
A19: 4655 | B19: محسن نوربخش | C19: 2 | D19: 12960000 | E19: 21000000
A20: 4656 | B20: عباس اوتادی | C20: 2 | D20: 32400000
A21: 4657 | B21: مجتبی جواهری فرید | C21: 2 | D21: 25920000
A22: 4658 | B22: علیرضا محمودیان | C22: 2 | D22: 19440000
A23: 4660 | B23: علی مینائی حفظ آباد | C23: 2 | D23: 25920000 | E23: 40000000
A24: 4661 | B24: مسعود نوربخش | C24: 2 | D24: 25920000
A25: 4663 | B25: عباس محمدی | C25: 2 | D25: 51840000
A26: 4664 | B26: حسین عزتی عابد | C26: 2 | D26: 25920000
A27: 4665 | B27: سیدرسول حسینی | C27: 2 | E27: 40000000
A28: 4666 | B28: محمد فکری | C28: 2 | D28: 19440000 | E28: 16000000
A29: 4667 | B29: محسن ذاکری | C29: 2
A30: 4668 | B30: رضا غریب زاد | C30: 2 | D30: 25920000
A31: 4669 | B31: محسن طاهری سیاح | C31: 2 | D31: 45360000
A32: 4670 | B32: سجاد حیدری | C32: 2 | D32: 19440000
A33: 4671 | B33: عبداله جعفری | C33: 2 | D33: 19440000 | E33: 10000000
A34: 4673 | B34: رسول بابائی | C34: 2 | D34: 19440000
A35: 4686 | B35: سیده سپنتا سیدصالحی | C35: 2 | D35: 12960000
A36: 4687 | B36: سیدآرش وکیلیان | C36: 2
A37: 4688 | B37: مصطفی علیئی | C37: 2 | D37: 25920000 | E37: 40000000
A38: 4689 | B38: سیدمحمدهادی حیدری | C38: 2 | D38: 12960000
A39: 4693 | B39: هلیا یوسف نژاد میاندهی | C39: 2 | D39: 6480000
A40: 4701 | B40: محمدحسین سیاح طاهری | C40: 2
...

Sheet خرداد
A1: کد پرسنلی | B1: نام و نام خانوادگی کارمند | C1: ماه | D1: بیمه درمان تکمیلی | E1: جمع اقساط وام | F1: صندوق کارکنان مامور | G1: کسورات غذا
A2: 1905 | B2: مجتبی جعفری | C2: 3 | D2: 0 | E2: 0 | F2: 0
A3: 3567 | B3: محمدمهدی نصرهرندی | C3: 3 | D3: 0 | E3: 0 | F3: 0
A4: 3607 | B4: امیررضا مومن | C4: 3 | D4: 32400000 | E4: 0 | F4: 0
A5: 3653 | B5: محمدعلی پیوست | C5: 3 | D5: 32400000 | E5: 0 | F5: 0
A6: 4590 | B6: معصومه توانای خشگرودی | C6: 3 | D6: 0 | E6: 0 | F6: 0
A7: 4597 | B7: مجید محمدی | C7: 3 | D7: 25920000 | E7: 0 | F7: 0
A8: 4598 | B8: سیدمهدی میری | C8: 3 | D8: 25920000 | E8: 40000000 | F8: 0
A9: 4614 | B9: محمد مهدی اطهر | C9: 3 | D9: 19440000 | E9: 0 | F9: 0
A10: 4621 | B10: سیدعباس مرادی | C10: 3 | D10: 0 | E10: 13285793 | F10: 0
A11: 4622 | B11: محمدرضا احمدلو | C11: 3 | D11: 25920000 | E11: 0 | F11: 0
A12: 4636 | B12: سید مصطفی معصوم پور | C12: 3 | D12: 32400000 | E12: 0 | F12: 0
A13: 4640 | B13: سیده فاطمه شجاعیان | C13: 3 | D13: 19440000 | E13: 0 | F13: 0
... A231: 9015 | B231: امیر خوراکیان | C231: 3 | D231: 6480000 | E231: 0 | F231: 0

Sheet حق ماموریت تیر
A1: کد پرسنلی | B1: نام و نام خانوادگی کارمند | C1: شناسه کاربر | D1: ماه | E1: حق ماموریت
A2: 1905 | B2: مجتبی جعفری | C2: 8 | D2: 4 | E2: 6571530
A3: 3653 | B3: محمدعلی پیوست | C3: 34 | D3: 4 | E3: 7295067
A4: 4636 | B4: سید مصطفی معصوم پور | C4: 62 | D4: 4 | E4: 6780150
A5: 4660 | B5: علی مینائی حفظ آباد | C5: 72 | D5: 4 | E5: 3182723
A6: 4661 | B6: مسعود نوربخش | C6: 63 | D6: 4 | E6: 3347699
A7: 4665 | B7: سیدرسول حسینی | C7: 64 | D7: 4 | E7: 2754341
A8: 4669 | B8: محسن طاهری سیاح | C8: 68 | D8: 4 | E8: 10401366
A9: 5685 | B9: ابوالقاسم خداوردیلو | C9: 142 | D9: 4 | E9: 4204544
A10: 5744 | B10: جواد آزادی احمدآبادی | C10: 3 | D10: 4 | E10: 30849011
A11: 5863 | B11: سیدمحمدامین آقامیری | C11: 2 | D11: 4 | E11: 43958845
A12: 5870 | B12: علی آیدینی | C12: 199 | D12: 4 | E12: 21417389
A13: 5898 | B13: محمد مهدی حق بین | C13: 29 | D13: 4 | E13: 18509406
... A23: 6020 | B23: حسین طاهری | C23: 425 | D23: 4 | E23: 21731250

Sheet تیر
A1: کد پرسنلی | B1: نام و نام خانوادگی کارمند | C1: شناسه کاربر | D1: ماه | E1: سایر کسور | F1: بیمه درمان تکمیلی | G1: جمع اقساط وام | H1: صندوق کارکنان مامور
A2: 3567 | B2: محمدمهدی نصرهرندی | C2: 57 | D2: 4 | E2: 7500000 | F2: 0 | G2: 0 | H2: 0
A3: 3607 | B3: امیررضا مومن | C3: 119 | D3: 4 | E3: 0 | F3: 32400000 | G3: 0 | H3: 0
A4: 3653 | B4: محمدعلی پیوست | C4: 34 | D4: 4 | E4: 1500000 | F4: 32400000 | G4: 0 | H4: 0
A5: 4597 | B5: مجید محمدی | C5: 38 | D5: 4 | E5: 4000000 | F5: 25920000 | G5: 0 | H5: 0
A6: 4598 | B6: سیدمهدی میری | C6: 129 | D6: 4 | E6: 10500000 | F6: 25920000 | G6: 40000000 | H6: 0
A7: 4614 | B7: محمد مهدی اطهر | C7: 140 | D7: 4 | E7: 7114820 | F7: 19440000 | G7: 0 | H7: 0
A8: 4621 | B8: سیدعباس مرادی | C8: 139 | D8: 4 | E8: 0 | F8: 0 | G8: 13285793 | H8: 0
A9: 4622 | B9: محمدرضا احمدلو | C9: 35 | D9: 4 | E9: 0 | F9: 25920000 | G9: 0 | H9: 0
A10: 4636 | B10: سید مصطفی معصوم پور | C10: 62 | D10: 4 | E10: 0 | F10: 32400000 | G10: 0 | H10: 0
A11: 4640 | B11: سیده فاطمه شجاعیان | C11: 32 | D11: 4 | E11: 4478000 | F11: 19440000 | G11: 0 | H11: 0
A12: 4648 | B12: حسن شبانی | C12: 160 | D12: 4 | E12: 6000000 | F12: 19440000 | G12: 0 | H12: 0
A13: 4651 | B13: حسین حقیقت پور | C13: 52 | D13: 4 | E13: 4500000 | F13: 19440000 | G13: 0 | H13: 0
... A29: 4671 | B29: عبداله جعفری | C29: 73 | D29: 4 | E29: 1500000 | F29: 19440000 | G29: 75638888 | H29: 0
A30: 4673 | B30: رسول بابائی | D30: 4 | E30: 3000000 | F30: 19440000 | G30: 0 | H30: 0
A31: 4686 | B31: سیده سپنتا سیدصالحی | C31: 27 | D31: 4 | E31: 2120000 | F31: 12960000 | G31: 0 | H31: 0
A32: 4687 | B32: سیدآرش وکیلیان | C32: 136 | D32: 4 | E32: 3000000 | F32: 0 | G32: 0 | H32: 0
A33: 4688 | B33: مصطفی علیئی | C33: 143 | D33: 4 | E33: 1500000 | F33: 25920000 | G33: 0 | H33: 0
A34: 4689 | B34: سیدمحمدهادی حیدری | C34: 96 | D34: 4 | E34: 0 | F34: 12960000 | G34: 0 | H34: 0
A35: 4693 | B35: هلیا یوسف نژاد میاندهی | C35: 24 | D35: 4 | E35: 1500000 | F35: 6480000 | G35: 0 | H35: 0
A36: 4701 | B36: محمدحسین سیاح طاهری | C36: 138 | D36: 4 | E36: 4500000 | F36: 0 | G36: 0 | H36: 0
A37: 4705 | B37: سیدمسعود حسین پورمشگانی | C37: 134 | D37: 4 | E37: 1500000 | F37: 6480000 | G37: 0 | H37: 0
A38: 4727 | B38: بیتا بزازان | C38: 58 | D38: 4 | E38: 0 | F38: 6480000 | G38: 0 | H38: 0
A39: 4728 | B39: رؤیا سادات امامی خوانساری | C39: 144 | D39: 4 | E39: 0 | F39: 6480000 | G39: 0 | H39: 0
A40: 4735 | B40: علی دل زنده | C40: 141 | D40: 4 | E40: 0 | F40: 32400000 | G40: 0 | H40: 0
A41: 5616 | B41: اصغر قربانی | C41: 40 | D41: 4 | E41: 0 | F41: 32400000 | G41: 0 | H41: 0
A42: 5621 | B42: اسمعیل داداشی کلیان | C42: 97 | D42: 4 | E42: 0 | F42: 19440000 | G42: 0 | H42: 0
... A167: 6114 | B167: محمد هادی زرافشان | C167: 467 | D167: 4 | E167: 0 | F167: 38880000 | G167: 0 | H167: 0

Sheet مرداد
A1: کد پرسنلی | B1: نام و نام خانوادگی کارمند | C1: شناسه کاربر | D1: ماه | E1: بیمه درمان تکمیلی | F1: جمع اقساط وام | G1: صندوق کارکنان مامور | H1: سایر کسور
A2: 3607 | B2: امیررضا مومن | C2: 119 | D2: 5 | E2: 32400000 | F2: 0 | G2: 0 | H2: 0
A3: 3653 | B3: محمدعلی پیوست | C3: 34 | D3: 5 | E3: 32400000 | F3: 0 | G3: 0 | H3: 0
A4: 4597 | B4: مجید محمدی | C4: 38 | D4: 5 | E4: 25920000 | F4: 0 | G4: 0 | H4: 1586960
A5: 4598 | B5: سیدمهدی میری | C5: 129 | D5: 5 | E5: 25920000 | F5: 40000000 | G5: 0 | H5: 4500000
A6: 4614 | B6: محمد مهدی اطهر | C6: 140 | D6: 5 | E6: 19440000 | F6: 0 | G6: 0 | H6: 1500000
A7: 4621 | B7: سیدعباس مرادی | C7: 139 | D7: 5 | E7: 0 | F7: 13285793 | G7: 0 | H7: 0
A8: 4622 | B8: محمدرضا احمدلو | C8: 35 | D8: 5 | E8: 25920000 | F8: 0 | G8: 0 | H8: 6678000
A9: 4636 | B9: سید مصطفی معصوم پور | C9: 62 | D9: 5 | E9: 32400000 | F9: 0 | G9: 0 | H9: 0
A10: 4648 | B10: حسن شبانی | C10: 160 | D10: 5 | E10: 19440000 | F10: 0 | G10: 0 | H10: 0
A11: 4651 | B11: حسین حقیقت پور | C11: 52 | D11: 5 | E11: 19440000 | F11: 0 | G11: 0 | H11: 2677400
A12: 4654 | B12: مهران احمدی آذر | C12: 85 | D12: 5 | E12: 19440000 | F12: 40000000 | G12: 0 | H12: 0
A13: 4655 | B13: محسن نوربخش | C13: 122 | D13: 5 | E13: 12960000 | F13: 50000000 | G13: 0 | H13: 1500000
... A172: 6111 | B172: جواد سراج | C172: 451 | D172: 5 | E172: 0 | F172: 0 | G172: 0 | H172: 3000000

Sheet شهریور
A1: کد پرسنلی | B1: نام و نام خانوادگی کارمند | C1: شناسه کاربر | D1: ماه | E1: بیمه درمان تکمیلی | F1: جمع اقساط وام | G1: صندوق کارکنان مامور | H1: سایر کسور | I1: وام زیارت
A2: 3567 | B2: محمدمهدی نصرهرندی | C2: 57 | D2: 6 | E2: 0 | F2: 40000000 | G2: 0 | H2: 0 | I2: 0
A3: 3607 | B3: امیررضا مومن | C3: 119 | D3: 6 | E3: 32400000 | F3: 0 | G3: 0 | H3: 0 | I3: 0
A4: 3653 | B4: محمدعلی پیوست | C4: 34 | D4: 6 | E4: 32400000 | F4: 0 | G4: 0 | H4: 0 | I4: 0
A5: 4590 | B5: معصومه توانای خشگرودی | C5: 30 | D5: 6 | E5: 0 | F5: 40000000 | G5: 0 | H5: 0 | I5: 0
A6: 4597 | B6: مجید محمدی | C6: 38 | D6: 6 | E6: 25920000 | F6: 60000000 | G6: 0 | H6: 0 | I6: 0
A7: 4598 | B7: سیدمهدی میری | C7: 129 | D7: 6 | E7: 25920000 | F7: 40000000 | G7: 0 | H7: 0 | I7: 0
A8: 4614 | B8: محمد مهدی اطهر | C8: 140 | D8: 6 | E8: 19440000 | F8: 0 | G8: 0 | H8: 1500000 | I8: 0
A9: 4622 | B9: محمدرضا احمدلو | C9: 35 | D9: 6 | E9: 25920000 | F9: 0 | G9: 0 | H9: 1500000 | I9: 0
A10: 4636 | B10: سید مصطفی معصوم پور | C10: 62 | D10: 6 | E10: 32400000 | F10: 0 | G10: 0 | H10: 0 | I10: 0
A11: 4648 | B11: حسن شبانی | C11: 160 | D11: 6 | E11: 19440000 | F11: 0 | G11: 0 | H11: 0 | I11: 0
A12: 4651 | B12: حسین حقیقت پور | C12: 52 | D12: 6 | E12: 19440000 | F12: 0 | G12: 0 | H12: 2928000 | I12: 0
A13: 4654 | B13: مهران احمدی آذر | C13: 85 | D13: 6 | E13: 19440000 | F13: 40000000 | G13: 0 | H13: 0 | I13: 0
... A146: 9015 | B146: امیر خوراکیان | C146: 4 | D146: 6 | E146: 6480000 | F146: 0 | G146: 0 | H146: 0 | I146: 0

Sheet مهر
A1: کد پرسنلی | B1: نام و نام خانوادگی کارمند | C1: شناسه کاربر | D1: سال | E1: ماه | F1: بیمه درمان تکمیلی | G1: جمع اقساط وام | H1: صندوق کارکنان مامور | I1: سایر کسور
A2: 3567 | B2: محمدمهدی نصرهرندی | C2: 57 | D2: 1404 | E2: 7 | F2: 19900000 | G2: 40000000 | H2: 0 | I2: 0
A3: 3607 | B3: امیررضا مومن | C3: 119 | D3: 1404 | E3: 7 | F3: 49750000 | G3: 0 | H3: 0 | I3: 0
A4: 3653 | B4: محمدعلی پیوست | C4: 34 | D4: 1404 | E4: 7 | F4: 49750000 | G4: 0 | H4: 0 | I4: 6716000
A5: 4590 | B5: معصومه توانای خشگرودی | C5: 30 | D5: 1404 | E5: 7 | F5: 0 | G5: 40000000 | H5: 0 | I5: 0
A6: 4597 | B6: مجید محمدی | C6: 38 | D6: 1404 | E6: 7 | F6: 39800000 | G6: 60000000 | H6: 0 | I6: 2000000
A7: 4598 | B7: سیدمهدی میری | C7: 129 | D7: 1404 | E7: 7 | F7: 39800000 | G7: 40000000 | H7: 0 | I7: 0
A8: 4614 | B8: محمد مهدی اطهر | C8: 140 | D8: 1404 | E8: 7 | F8: 9950000 | G8: 0 | H8: 0 | I8: 4500000
A9: 4622 | B9: محمدرضا احمدلو | C9: 35 | D9: 1404 | E9: 7 | F9: 39800000 | G9: 0 | H9: 0 | I9: 3000000
A10: 4636 | B10: سید مصطفی معصوم پور | C10: 62 | D10: 1404 | E10: 7 | F10: 49750000 | G10: 0 | H10: 0 | I10: 0
A11: 4640 | B11: سیده فاطمه شجاعیان | C11: 32 | D11: 1404 | E11: 7 | F11: 0 | G11: 0 | H11: 0 | I11: 0
A12: 4643 | B12: سعید مهدیون | C12: 25 | D12: 1404 | E12: 7 | F12: 0 | G12: 0 | H12: 0 | I12: 0
A13: 4648 | B13: حسن شبانی | C13: 160 | D13: 1404 | E13: 7 | F13: 29850000 | G13: 0 | H13: 0 | I13: 2928000
... A180: 9015 | B180: امیر خوراکیان | C180: 4 | D180: 1404 | E180: 7 | F180: 9950000 | G180: 0 | H180: 0 | I180: 0
F181: 0 | G181: 0 | H181: 0 | I181: 0
F182: 0 | G182: 0 | H182: 0 | I182: 0
F183: 0 | G183: 0 | H183: 0 | I183: 0
F184: 0 | G184: 0 | H184: 0 | I184: 0
F185: 0 | G185: 0 | H185: 0 | I185: 0
F186: 0 | G186: 0 | H186: 0 | I186: 0
F187: 0 | G187: 0 | H187: 0 | I187: 0
F188: 0 | G188: 0 | H188: 0 | I188: 0
F189: 0 | G189: 0 | H189: 0 | I189: 0
F190: 0 | G190: 0 | H190: 0 | I190: 0
F191: 0 | G191: 0 | H191: 0 | I191: 0
F192: 0 | G192: 0 | H192: 0 | I192: 0
... F251: 0 | G251: 0 | H251: 0 | I251: 0

Sheet آبان
A1: کد پرسنلی | B1: نام و نام خانوادگی کارمند | C1: شناسه کاربر | D1: سال | E1: ماه | F1: بیمه درمان تکمیلی | G1: جمع اقساط وام | H1: صندوق کارکنان مامور | I1: سایر کسور
A2: 3567 | B2: محمدمهدی نصرهرندی | C2: =VLOOKUP(A2,مهر!A:C,3,0) -> 57 | D2: 1404 | E2: 8 | F2: 19900000 | G2: 40000000 | H2: 0 | I2: 1500000
A3: 3607 | B3: امیررضا مومن | C3: =VLOOKUP(A3,مهر!A:C,3,0) -> 119 | D3: 1404 | E3: 8 | F3: 49750000 | G3: 30000000 | H3: 0 | I3: 0
A4: 3653 | B4: محمدعلی پیوست | C4: =VLOOKUP(A4,مهر!A:C,3,0) -> 34 | D4: 1404 | E4: 8 | F4: 49750000 | G4: 0 | H4: 0 | I4: 6688000
A5: 4590 | B5: معصومه توانای خشگرودی | C5: =VLOOKUP(A5,مهر!A:C,3,0) -> 30 | D5: 1404 | E5: 8 | F5: 0 | G5: 40000000 | H5: 0 | I5: 0
A6: 4597 | B6: مجید محمدی | C6: =VLOOKUP(A6,مهر!A:C,3,0) -> 38 | D6: 1404 | E6: 8 | F6: 39800000 | G6: 60000000 | H6: 0 | I6: 0
A7: 4598 | B7: سیدمهدی میری | C7: =VLOOKUP(A7,مهر!A:C,3,0) -> 129 | D7: 1404 | E7: 8 | F7: 39800000 | G7: 0 | H7: 0 | I7: 0
A8: 4614 | B8: محمد مهدی اطهر | C8: =VLOOKUP(A8,مهر!A:C,3,0) -> 140 | D8: 1404 | E8: 8 | F8: 9950000 | G8: 0 | H8: 0 | I8: 3000000
A9: 4622 | B9: محمدرضا احمدلو | C9: =VLOOKUP(A9,مهر!A:C,3,0) -> 35 | D9: 1404 | E9: 8 | F9: 39800000 | G9: 30000000 | H9: 0 | I9: 0
A10: 4636 | B10: سید مصطفی معصوم پور | C10: =VLOOKUP(A10,مهر!A:C,3,0) -> 62 | D10: 1404 | E10: 8 | F10: 59700000 | G10: 100000000 | H10: 0 | I10: 0
A11: 4648 | B11: حسن شبانی | C11: =VLOOKUP(A11,مهر!A:C,3,0) -> 160 | D11: 1404 | E11: 8 | F11: 29850000 | G11: 0 | H11: 0 | I11: 0
A12: 4651 | B12: حسین حقیقت پور | C12: =VLOOKUP(A12,مهر!A:C,3,0) -> 52 | D12: 1404 | E12: 8 | F12: 69650000 | G12: 30000000 | H12: 0 | I12: 4464000
A13: 4654 | B13: مهران احمدی آذر | C13: =VLOOKUP(A13,مهر!A:C,3,0) -> 85 | D13: 1404 | E13: 8 | F13: 39800000 | G13: 40000000 | H13: 0 | I13: 945000
... A47: 5655 | B47: سید امیرحسین مکبری | C47: =VLOOKUP(A47,مهر!A:C,3,0) -> 130 | D47: 1404 | E47: 8 | F47: 29850000 | G47: 0 | H47: 0 | I47: 0
A48: 5663 | B48: محسن پاشا | C48: 524 | D48: 1404 | E48: 8 | F48: 0 | G48: 47700000 | H48: 0 | I48: 0
A49: 5671 | B49: مجید یاری | C49: =VLOOKUP(A49,مهر!A:C,3,0) -> 128 | D49: 1404 | E49: 8 | F49: 0 | G49: 0 | H49: 0 | I49: 3037100
A50: 5685 | B50: ابوالقاسم خداوردیلو | C50: =VLOOKUP(A50,مهر!A:C,3,0) -> 142 | D50: 1404 | E50: 8 | F50: 29850000 | G50: 0 | H50: 0 | I50: 0
A51: 5699 | B51: مجتبی نصیری یار | C51: =VLOOKUP(A51,مهر!A:C,3,0) -> 159 | D51: 1404 | E51: 8 | F51: 49750000 | G51: 0 | H51: 0 | I51: 0
A52: 5708 | B52: محمدعلی اسدی | C52: =VLOOKUP(A52,مهر!A:C,3,0) -> 50 | D52: 1404 | E52: 8 | F52: 29850000 | G52: 0 | H52: 0 | I52: 0
A53: 5710 | B53: مصطفی مرادی | C53: =VLOOKUP(A53,مهر!A:C,3,0) -> 74 | D53: 1404 | E53: 8 | F53: 29850000 | G53: 30000000 | H53: 0 | I53: 0
A54: 5727 | B54: مهدی جامعی | C54: =VLOOKUP(A54,مهر!A:C,3,0) -> 47 | D54: 1404 | E54: 8 | F54: 59700000 | G54: 50000000 | H54: 0 | I54: 0
A55: 5734 | B55: حسین قمری | C55: =VLOOKUP(A55,مهر!A:C,3,0) -> 98 | D55: 1404 | E55: 8 | F55: 19900000 | G55: 40000000 | H55: 0 | I55: 0
A56: 5744 | B56: جواد آزادی احمدآبادی | C56: =VLOOKUP(A56,مهر!A:C,3,0) -> 3 | D56: 1404 | E56: 8 | F56: 39800000 | G56: 187718500 | H56: 0 | I56: 0
A57: 5765 | B57: حبیب سلیمی ثابت | C57: =VLOOKUP(A57,مهر!A:C,3,0) -> 51 | D57: 1404 | E57: 8 | F57: 29850000 | G57: 0 | H57: 0 | I57: 0
A58: 5766 | B58: علی طاهری برمائی | C58: =VLOOKUP(A58,مهر!A:C,3,0) -> 135 | D58: 1404 | E58: 8 | F58: 29850000 | G58: 0 | H58: 0 | I58: 0
A59: 5771 | B59: مرتضی صالحی | C59: =VLOOKUP(A59,مهر!A:C,3,0) -> 77 | D59: 1404 | E59: 8 | F59: 19900000 | G59: 30000000 | H59: 0 | I59: 0
A60: 5783 | B60: علی کامرانی دستجردی | C60: =VLOOKUP(A60,مهر!A:C,3,0) -> 79 | D60: 1404 | E60: 8 | F60: 39800000 | G60: 20000000 | H60: 0 | I60: 0
... A82: 5900 | B82: حامد خورسند | C82: =VLOOKUP(A82,مهر!A:C,3,0) -> 42 | D82: 1404 | E82: 8 | F82: 9950000 | G82: 30000000 | H82: 0 | I82: 0
A83: 5905 | B83: محمد امین اله داد | C83: 498 | D83: 1404 | E83: 8 | F83: 0 | G83: 15786166 | H83: 0 | I83: 0
A84: 5907 | B84: سید مرتضی حسنی | C84: =VLOOKUP(A84,مهر!A:C,3,0) -> 16 | D84: 1404 | E84: 8 | F84: 29850000 | G84: 118348832 | H84: 0 | I84: 0
A85: 5908 | B85: مصطفی محمدی | C85: =VLOOKUP(A85,مهر!A:C,3,0) -> 156 | D85: 1404 | E85: 8 | F85: 0 | G85: 30000000 | H85: 0 | I85: 0
A86: 5909 | B86: جواد جواهری | C86: =VLOOKUP(A86,مهر!A:C,3,0) -> 23 | D86: 1404 | E86: 8 | F86: 39800000 | G86: 0 | H86: 0 | I86: 0
A87: 5914 | B87: حمیدرضا زندی طغان | C87: =VLOOKUP(A87,مهر!A:C,3,0) -> 14 | D87: 1404 | E87: 8 | F87: 0 | G87: 129999999 | H87: 0 | I87: 0
A88: 5918 | B88: مجید جاودانی ملاک | C88: =VLOOKUP(A88,مهر!A:C,3,0) -> 9 | D88: 1404 | E88: 8 | F88: 39800000 | G88: 45853333 | H88: 0 | I88: 0
A89: 5919 | B89: سجاد عبدالهی | C89: =VLOOKUP(A89,مهر!A:C,3,0) -> 152 | D89: 1404 | E89: 8 | F89: 39800000 | G89: 0 | H89: 0 | I89: 4000000
A90: 5924 | B90: امیرحسین غلامزاده بوجاری | C90: =VLOOKUP(A90,مهر!A:C,3,0) -> 54 | D90: 1404 | E90: 8 | F90: 19900000 | G90: 80000000 | H90: 0 | I90: 0
A91: 5926 | B91: سهراب کرمی | C91: =VLOOKUP(A91,مهر!A:C,3,0) -> 112 | D91: 1404 | E91: 8 | F91: 39800000 | G91: 90000000 | H91: 0 | I91: 26970388
A92: 5927 | B92: امیر مهدی ادیب | C92: =VLOOKUP(A92,مهر!A:C,3,0) -> 153 | D92: 1404 | E92: 8 | F92: 9950000 | G92: 30000000 | H92: 0 | I92: 1500000
A93: 5931 | B93: ابراهیم برزگر | C93: =VLOOKUP(A93,مهر!A:C,3,0) -> 113 | D93: 1404 | E93: 8 | F93: 39800000 | G93: 40000000 | H93: 0 | I93: 0
A94: 5936 | B94: حسین دلیریان | C94: =VLOOKUP(A94,مهر!A:C,3,0) -> 11 | D94: 1404 | E94: 8 | F94: 39800000 | G94: 150804500 | H94: 0 | I94: 0
...

Sheet آذر
A1: کد پرسنلی | B1: نام و نام خانوادگی کارمند | C1: شناسه کاربر | D1: سال | E1: ماه | F1: بیمه درمان تکمیلی | G1: جمع اقساط وام | H1: صندوق کارکنان مامور | I1: سایر کسور
A2: 3653 | B2: محمدعلی پیوست | C2: =VLOOKUP(A2,آبان!A:C,3,0) -> 34 | D2: 1404 | E2: 9 | F2: 49750000 | G2: 0 | H2: 0 | I2: 6172000
A3: 4598 | B3: سیدمهدی میری | C3: =VLOOKUP(A3,آبان!A:C,3,0) -> 129 | D3: 1404 | E3: 9 | F3: 39800000 | G3: 0 | H3: 0 | I3: 3900000
A4: 4636 | B4: سید مصطفی معصوم پور | C4: =VLOOKUP(A4,آبان!A:C,3,0) -> 62 | D4: 1404 | E4: 9 | F4: 59700000 | G4: 100000000 | H4: 0 | I4: 0
A5: 4687 | B5: سیدآرش وکیلیان | C5: =VLOOKUP(A5,آبان!A:C,3,0) -> 136 | D5: 1404 | E5: 9 | F5: 39800000 | G5: 0 | H5: 0 | I5: 13000000
A6: 5655 | B6: سید امیرحسین مکبری | C6: =VLOOKUP(A6,آبان!A:C,3,0) -> 130 | D6: 1404 | E6: 9 | F6: 29850000 | G6: 40000000 | H6: 0 | I6: 0
A7: 5699 | B7: مجتبی نصیری یار | C7: =VLOOKUP(A7,آبان!A:C,3,0) -> 159 | D7: 1404 | E7: 9 | F7: 49750000 | G7: 0 | H7: 0 | I7: 13900000
A8: 5883 | B8: محمدمهدی آقامحمدحسین تجریشی | C8: =VLOOKUP(A8,آبان!A:C,3,0) -> 6 | D8: 1404 | E8: 9 | F8: 59700000 | G8: 95434000 | H8: 21887016 | I8: 0
A9: 3567 | B9: محمدمهدی نصرهرندی | C9: =VLOOKUP(A9,آبان!A:C,3,0) -> 57 | D9: 1404 | E9: 9 | F9: 19900000 | G9: 40000000 | H9: 0 | I9: 2700000
A10: 3607 | B10: امیررضا مومن | C10: =VLOOKUP(A10,آبان!A:C,3,0) -> 119 | D10: 1404 | E10: 9 | F10: 49750000 | G10: 30000000 | H10: 0 | I10: 4500000
A11: 4614 | B11: محمد مهدی اطهر | C11: =VLOOKUP(A11,آبان!A:C,3,0) -> 140 | D11: 1404 | E11: 9 | F11: 9950000 | G11: 0 | H11: 0 | I11: 9200000
A12: 4622 | B12: محمدرضا احمدلو | C12: =VLOOKUP(A12,آبان!A:C,3,0) -> 35 | D12: 1404 | E12: 9 | F12: 39800000 | G12: 30000000 | H12: 0 | I12: 0
A13: 4648 | B13: حسن شبانی | C13: =VLOOKUP(A13,آبان!A:C,3,0) -> 160 | D13: 1404 | E13: 9 | F13: 29850000 | G13: 0 | H13: 0 | I13: 6000000
... A69: 5952 | B69: محمد مهدی چگینی | C69: =VLOOKUP(A69,آبان!A:C,3,0) -> 307 | D69: 1404 | E69: 9 | F69: 0 | G69: 30000000 | H69: 0 | I69: 0
A70: 5970 | B70: سجاد خلیلی نژاد | C70: 204 | D70: 1404 | E70: 9 | F70: 0 | G70: 0 | H70: 0 | I70: 2900000
A71: 5971 | B71: حسین زیبنده | C71: 203 | D71: 1404 | E71: 9 | F71: 0 | G71: 0 | H71: 0 | I71: 600000
A72: 6000 | B72: منصور اعلمی | C72: =VLOOKUP(A72,آبان!A:C,3,0) -> 363 | D72: 1404 | E72: 9 | F72: 0 | G72: 0 | H72: 0 | I72: 1500000
A73: 6001 | B73: سیدطه رضا نیرهدی | C73: =VLOOKUP(A73,آبان!A:C,3,0) -> 366 | D73: 1404 | E73: 9 | F73: 49750000 | G73: 0 | H73: 0 | I73: 0
A74: 6014 | B74: محمد حسین ولیخانی | C74: 319 | D74: 1404 | E74: 9 | F74: 0 | G74: 0 | H74: 0 | I74: 3900000
A75: 6124 | B75: سید محمد جواد طباطبایی فر | C75: =VLOOKUP(A75,آبان!A:C,3,0) -> 455 | D75: 1404 | E75: 9 | F75: 0 | G75: 30000000 | H75: 0 | I75: 12700000
A76: 6128 | B76: فاطمه یوسف معمار | C76: 493 | D76: 1404 | E76: 9 | F76: 0 | G76: 0 | H76: 0 | I76: 2700000
A77: 6129 | B77: علی جامی خراسانی | C77: =VLOOKUP(A77,آبان!A:C,3,0) -> 494 | D77: 1404 | E77: 9 | F77: 0 | G77: 0 | H77: 0 | I77: 12100000
A78: 6189 | B78: طاها ذی قیمت | C78: 597 | D78: 1404 | E78: 9 | F78: 0 | G78: 0 | H78: 0 | I78: 2100000
A79: 5863 | B79: سیدمحمدامین آقامیری | C79: =VLOOKUP(A79,آبان!A:C,3,0) -> 2 | D79: 1404 | E79: 9 | F79: 39800000 | G79: 194702857 | H79: 0 | I79: 0
A80: 5890 | B80: میثم غلامی خلیل آباد | C80: =VLOOKUP(A80,آبان!A:C,3,0) -> 15 | D80: 1404 | E80: 9 | F80: 49750000 | G80: 0 | H80: 0 | I80: 2700000
A81: 5918 | B81: مجید جاودانی ملاک | C81: =VLOOKUP(A81,آبان!A:C,3,0) -> 9 | D81: 1404 | E81: 9 | F81: 39800000 | G81: 45853333 | H81: 0 | I81: 0
A82: 6093 | B82: محمد صادق فراهانی | C82: =VLOOKUP(A82,آبان!A:C,3,0) -> 447 | D82: 1404 | E82: 9 | F82: 39800000 | G82: 77717000 | H82: 0 | I82: 2400000
A83: 5638 | B83: امیرحسین آستانه ها | C83: =VLOOKUP(A83,آبان!A:C,3,0) -> 87 | D83: 1404 | E83: 9 | F83: 19900000 | G83: 0 | H83: 0 | I83: 22400000
A84: 5744 | B84: جواد آزادی احمدآبادی | C84: =VLOOKUP(A84,آبان!A:C,3,0) -> 3 | D84: 1404 | E84: 9 | F84: 39800000 | G84: 117718500 | H84: 0 | I84: 3900000
A85: 5766 | B85: علی طاهری برمائی | C85: =VLOOKUP(A85,آبان!A:C,3,0) -> 135 | D85: 1404 | E85: 9 | F85: 29850000 | G85: 0 | H85: 0 | I85: 1500000
A86: 5771 | B86: مرتضی صالحی | C86: =VLOOKUP(A86,آبان!A:C,3,0) -> 77 | D86: 1404 | E86: 9 | F86: 19900000 | G86: 30000000 | H86: 0 | I86: 0
A87: 5783 | B87: علی کامرانی دستجردی | C87: =VLOOKUP(A87,آبان!A:C,3,0) -> 79 | D87: 1404 | E87: 9 | F87: 39800000 | G87: 20000000 | H87: 0 | I87: 0
A88: 5784 | B88: رقیه نورالهی فیض | C88: =VLOOKUP(A88,آبان!A:C,3,0) -> 148 | D88: 1404 | E88: 9 | F88: 9950000 | G88: 20000000 | H88: 0 | I88: 0
A89: 5791 | B89: رسول عرب سرخی میشابی | C89: =VLOOKUP(A89,آبان!A:C,3,0) -> 150 | D89: 1404 | E89: 9 | F89: 9950000 | G89: 0 | H89: 0 | I89: 6495000
A90: 5793 | B90: زینب السادات لاجوردی | C90: =VLOOKUP(A90,آبان!A:C,3,0) -> 43 | D90: 1404 | E90: 9 | F90: 0 | G90: 70000000 | H90: 0 | I90: 18000000
... A92: 5816 | B92: سید محمدرضا متقی | C92: =VLOOKUP(A92,آبان!A:C,3,0) -> 86 | D92: 1404 | E92: 9 | F92: 0 | G92: 0 | H92: 0 | I92: 600000
A93: 5824 | B93: سعید فتحعلی | C93: 41 | D93: 1404 | E93: 9 | F93: 0 | G93: 0 | H93: 0 | I93: 13000000
A94: 5827 | B94: فاطمه قاضیان | C94: =VLOOKUP(A94,آبان!A:C,3,0) -> 53 | D94: 1404 | E94: 9 | F94: 0 | G94: 90000000 | H94: 0 | I94: 4500000
A95: 5837 | B95: محمدرضا خلیلی | C95: =VLOOKUP(A95,آبان!A:C,3,0) -> 75 | D95: 1404 | E95: 9 | F95: 9950000 | G95: 0 | H95: 0 | I95: 5872600
A96: 5842 | B96: زهرا اشرفی حبیب آبادی | C96: 147 | D96: 1404 | E96: 9 | F96: 29850000 | G96: 0 | H96: 0 | I96: 0
...

Sheet دی
A1: کد پرسنلی | B1: نام و نام خانوادگی کارمند | C1: شناسه کاربر | D1: سال | E1: ماه | F1: بیمه درمان تکمیلی | G1: جمع اقساط وام | H1: صندوق کارکنان مامور | I1: کسورات غذا | J1: کسورات دیجی پی | K1: کسورات مشهد
A2: 3567 | B2: محمدمهدی نصرهرندی | C2: 57 | D2: 1404 | E2: 10 | F2: 19900000 | G2: 40000000 | H2: 0 | I2: 4500000 | J2: 0 | K2: 0
A3: 3607 | B3: امیررضا مومن | C3: 119 | D3: 1404 | E3: 10 | F3: 49750000 | G3: 30000000 | H3: 0 | I3: 5400000 | J3: 0 | K3: 0
A4: 3653 | B4: محمدعلی پیوست | C4: 34 | D4: 1404 | E4: 10 | F4: 49750000 | G4: 0 | H4: 0 | I4: 5400000 | J4: 0 | K4: 0
A5: 4590 | B5: معصومه توانای خشگرودی | C5: 30 | D5: 1404 | E5: 10 | F5: 0 | G5: 40000000 | H5: 0 | I5: 0 | J5: 0 | K5: 0
A6: 4597 | B6: مجید محمدی | C6: 38 | D6: 1404 | E6: 10 | F6: 39800000 | G6: 60000000 | H6: 0 | I6: 0 | J6: 0 | K6: 0
A7: 4598 | B7: سیدمهدی میری | C7: 129 | D7: 1404 | E7: 10 | F7: 39800000 | G7: 40000000 | H7: 0 | I7: 5400000 | J7: 0 | K7: 0
A8: 4614 | B8: محمد مهدی اطهر | C8: 140 | D8: 1404 | E8: 10 | F8: 9950000 | G8: 0 | H8: 0 | I8: 5400000 | J8: 0 | K8: 0
A9: 4622 | B9: محمدرضا احمدلو | C9: 35 | D9: 1404 | E9: 10 | F9: 39800000 | G9: 30000000 | H9: 0 | I9: 0 | J9: 0 | K9: 0
A10: 4636 | B10: سید مصطفی معصوم پور | C10: 62 | D10: 1404 | E10: 10 | F10: 59700000 | G10: 100000000 | H10: 0 | I10: 0 | J10: 0 | K10: 0
A11: 4648 | B11: حسن شبانی | C11: 160 | D11: 1404 | E11: 10 | F11: 29850000 | G11: 0 | H11: 0 | I11: 5400000 | J11: 0 | K11: 0
A12: 4651 | B12: حسین حقیقت پور | C12: 52 | D12: 1404 | E12: 10 | F12: 69650000 | G12: 30000000 | H12: 0 | I12: 18000000 | J12: 0 | K12: 0
A13: 4654 | B13: مهران احمدی آذر | C13: 85 | D13: 1404 | E13: 10 | F13: 39800000 | G13: 0 | H13: 0 | I13: 3600000 | J13: 0 | K13: 0
... A206: 6447 | B206: سعید ارادتی | C206: 91 | D206: 1404 | E206: 10 | F206: 29850000 | G206: 0 | H206: 0 | I206: 0 | J206: 0 | K206: 0

Sheet بهمن
A1: کد پرسنلی | B1: نام و نام خانوادگی کارمند | C1: شناسه کاربر | D1: سال | E1: ماه | F1: بیمه درمان تکمیلی | G1: جمع اقساط وام | H1: صندوق کارکنان مامور | I1: کسورات دیجی پی | J1: کسورات مشهد | K1: کسورات غذا
A2: 3567 | B2: محمدمهدی نصرهرندی | C2: =VLOOKUP(A2,دی!A:C,3,0) -> 57 | D2: 1404 | E2: 11 | F2: 19900000 | G2: 0 | H2: 0 | I2: 0 | J2: 0 | K2: 9300000
A3: 3607 | B3: امیررضا مومن | C3: =VLOOKUP(A3,دی!A:C,3,0) -> 119 | D3: 1404 | E3: 11 | F3: 49750000 | G3: 30000000 | H3: 0 | I3: 0 | J3: 0 | K3: 8800000
A4: 3653 | B4: محمدعلی پیوست | C4: =VLOOKUP(A4,دی!A:C,3,0) -> 34 | D4: 1404 | E4: 11 | F4: 49750000 | G4: 0 | H4: 0 | I4: 0 | J4: 0 | K4: 11600000
A5: 4590 | B5: معصومه توانای خشگرودی | C5: =VLOOKUP(A5,دی!A:C,3,0) -> 30 | D5: 1404 | E5: 11 | F5: 0 | G5: 60000000 | H5: 0 | I5: 0 | J5: 0 | K5: 0
A6: 4597 | B6: مجید محمدی | C6: =VLOOKUP(A6,دی!A:C,3,0) -> 38 | D6: 1404 | E6: 11 | F6: 39800000 | G6: 0 | H6: 0 | I6: 0 | J6: 0 | K6: 2000000
A7: 4598 | B7: سیدمهدی میری | C7: =VLOOKUP(A7,دی!A:C,3,0) -> 129 | D7: 1404 | E7: 11 | F7: 39800000 | G7: 40000000 | H7: 0 | I7: 0 | J7: 0 | K7: 12200000
A8: 4614 | B8: محمد مهدی اطهر | C8: =VLOOKUP(A8,دی!A:C,3,0) -> 140 | D8: 1404 | E8: 11 | F8: 9950000 | G8: 0 | H8: 0 | I8: 0 | J8: 0 | K8: 15600000
A9: 4622 | B9: محمدرضا احمدلو | C9: =VLOOKUP(A9,دی!A:C,3,0) -> 35 | D9: 1404 | E9: 11 | F9: 39800000 | G9: 30000000 | H9: 0 | I9: 0 | J9: 0 | K9: 0
A10: 4636 | B10: سید مصطفی معصوم پور | C10: =VLOOKUP(A10,دی!A:C,3,0) -> 62 | D10: 1404 | E10: 11 | F10: 59700000 | G10: 100000000 | H10: 0 | I10: 0 | J10: 0 | K10: 0
A11: 4648 | B11: حسن شبانی | C11: =VLOOKUP(A11,دی!A:C,3,0) -> 160 | D11: 1404 | E11: 11 | F11: 29850000 | G11: 0 | H11: 0 | I11: 0 | J11: 0 | K11: 12200000
A12: 4651 | B12: حسین حقیقت پور | C12: =VLOOKUP(A12,دی!A:C,3,0) -> 52 | D12: 1404 | E12: 11 | F12: 69650000 | G12: 30000000 | H12: 0 | I12: 0 | J12: 0 | K12: 36000000
A13: 4654 | B13: مهران احمدی آذر | C13: =VLOOKUP(A13,دی!A:C,3,0) -> 85 | D13: 1404 | E13: 11 | F13: 39800000 | G13: 0 | H13: 0 | I13: 0 | J13: 0 | K13: 8500000
... A195: 5833 | B195: سلمان صفدری | C195: =VLOOKUP(A195,دی!A:C,3,0) -> 125 | D195: 1404 | E195: 11 | F195: 0 | G195: 0 | H195: 0 | I195: 0 | J195: 0 | K195: 4100000
A196: 6206 | B196: محمدرضا ارجمندنیا | C196: 0 | D196: 1404 | E196: 11 | F196: 0 | G196: 0 | H196: 0 | I196: 0 | J196: 0 | K196: 3900000
A197: 5971 | B197: حسین زیبنده | C197: =VLOOKUP(A197,دی!A:C,3,0) -> 203 | D197: 1404 | E197: 11 | F197: 0 | G197: 0 | H197: 0 | I197: 0 | J197: 0 | K197: 3800000
A198: 6128 | B198: فاطمه یوسف معمار | C198: 0 | D198: 1404 | E198: 11 | F198: 0 | G198: 0 | H198: 0 | I198: 0 | J198: 0 | K198: 3000000
A199: 5970 | B199: سجاد خلیلی نژاد | C199: =VLOOKUP(A199,دی!A:C,3,0) -> 204 | D199: 1404 | E199: 11 | F199: 0 | G199: 0 | H199: 0 | I199: 0 | J199: 0 | K199: 2100000
A200: 5829 | B200: سیدهادی حسینی پنجکی | C200: =VLOOKUP(A200,دی!A:C,3,0) -> 56 | D200: 1404 | E200: 11 | F200: 0 | G200: 0 | H200: 0 | I200: 0 | J200: 0 | K200: 1200000
A201: 6217 | B201: سید علیرضا نجات | C201: 0 | D201: 1404 | E201: 11 | F201: 0 | G201: 0 | H201: 0 | I201: 0 | J201: 0 | K201: 600000
A202: 5816 | B202: سیدمحمدرضا متقی | C202: =VLOOKUP(A202,دی!A:C,3,0) -> 86 | D202: 1404 | E202: 11 | F202: 0 | G202: 0 | H202: 0 | I202: 0 | J202: 0 | K202: 6537800
A203: 6196 | B203: سمیه عبدالهی طایفه بسطام | C203: 0 | D203: 1404 | E203: 11 | F203: 0 | G203: 0 | H203: 0 | I203: 0 | J203: 0 | K203: 300000
A204: 5638 | B204: امیرحسین آستانه ها | C204: 0 | D204: 1404 | E204: 11 | F204: 0 | G204: 0 | H204: 0 | I204: 0 | J204: 0 | K204: 3000000
